<?xml version="1.0"?>
<robot name="two_dof_robot_arm">

  <!-- Base Link -->
  <link name="base_link">
    <visual>
      <geometry>
        <cylinder length="0.1" radius="0.05"/>
      </geometry>
      <material name="black"/>
    </visual>
  </link>

  <!-- Link1 -->
  <link name="link1">
    <visual>
      <geometry>
        <cylinder length="0.5" radius="0.02"/>
      </geometry>
      <material name="blue"/>
    </visual>
  </link>

  <!-- Link2 -->
  <link name="link2">
    <visual>
      <geometry>
        <cylinder length="0.3" radius="0.02"/>
      </geometry>
      <material name="green"/>
    </visual>
  </link>

  <!-- Joint1 -->
  <joint name="joint1" type="revolute">
    <parent link="base_link"/>
    <child link="link1"/>
    <origin xyz="0 0 0.05" rpy="0 0 0"/>
    <axis xyz="0 0 1"/>
    <limit lower="-1.57" upper="1.57" effort="1000" velocity="0.5"/>
  </joint>

  <!-- Joint2 -->
  <joint name="joint2" type="revolute">
    <parent link="link1"/>
    <child link="link2"/>
    <origin xyz="0 0 0.25" rpy="0 0 0"/>
    <axis xyz="0 0 1"/>
    <limit lower="-1.57" upper="1.57" effort="1000" velocity="0.5"/>
  </joint>

</robot>
